Workbook

Sheet Petunjuk
A1: PETUNJUK PENGGUNAAN
A2: Seleksi Mahasiswa Magang — Kantor Akuntan Publik
A4: TUJUAN
A5: Menyaring mahasiswa yang sudah memiliki dasar akuntansi dan audit, sehingga auditor tidak perlu menjelaskan dari nol.
A6: Mengukur kesiapan untuk tugas utama magang: vouching dokumen, observasi stock opname, dan pemeriksaan aset tetap.
A7: Menghasilkan penilaian yang konsisten meskipun interviewer bergantian.
A9: ALUR SELEKSI
A10: 1. Penyaringan awal: periksa transkrip/KRS. Undang wawancara hanya kandidat yang memenuhi syarat A1.
A11: 2. Duplikasi sheet 'Form Wawancara' untuk setiap kandidat (klik kanan tab → Move or Copy → Create a copy). Ganti nama sheet dengan nama kandidat.
A12: 3. Bagian A: tanyakan syarat administratif. Jika status 'GUGUR', wawancara teknis tidak perlu dilanjutkan.
A13: 4. Bagian B: ajukan 16 pertanyaan lisan (±35 menit) dan tes praktik Excel (15 menit, file terpisah). Total ±50–60 menit.
A14: 5. Beri skor 1–4 berdasarkan sheet 'Kunci & Rubrik'. Catat bukti/kutipan jawaban di kolom catatan.
... A33: Sheet 'Kunci & Rubrik' dan 'Kunci Tes Excel' tidak boleh diperlihatkan kepada kandidat.
A35: Contoh sel isian | B35: Contoh: Ringkasan jawaban kandidat

Sheet Form Wawancara
A1: FORM WAWANCARA SELEKSI MAHASISWA MAGANG
A2: Kantor Akuntan Publik | Satu sheet untuk satu kandidat (duplikasi sheet ini untuk kandidat berikutnya) | Isi hanya sel berwarna blush
A4: IDENTITAS KANDIDAT & WAWANCARA
A5: Nama Mahasiswa | E5: Tanggal Wawancara
A6: NIM | E6: Nama Interviewer
A7: Universitas | E7: Jabatan Interviewer
A8: Program Studi | E8: Periode Magang Diajukan
A9: Semester / IPK | E9: No. HP / Email
A10: Nilai MK Pengantar Akuntansi / Auditing I | E10: Durasi Wawancara (menit)
A12: BAGIAN A — SYARAT ADMINISTRATIF & SYARAT GUGUR (diisi sebelum wawancara teknis)
A13: No. | B13: Syarat | D13: Keterangan dari Kandidat | E13: Jawaban (Ya/Tidak) | F13: Bersifat Gugur? | G13: Status | H13: Catatan Interviewer
A14: A1 | B14: Telah lulus Pengantar Akuntansi dan minimal sedang menempuh Auditing I (dibuktikan dengan transkrip/KRS). | F14: Ya | G14: =IF(E14="","Belum diisi",IF(AND(F14="Ya",E14="Tidak"),"GUGUR",IF(E14="Ya","Memenuhi","Informasi – perhatikan")))
A15: A2 | B15: Dapat hadir penuh selama ±3 bulan pada hari dan jam kerja kantor, tidak bentrok dengan jadwal kuliah wajib. | F15: Ya | G15: =IF(E15="","Belum diisi",IF(AND(F15="Ya",E15="Tidak"),"GUGUR",IF(E15="Ya","Memenuhi","Informasi – perhatikan")))
A16: A3 | B16: Bersedia ikut kunjungan ke lokasi klien dalam kota (stock opname, pemeriksaan aset tetap), termasuk di luar jam kerja bila opname dijadwalkan demikian. | F16: Ya | G16: =IF(E16="","Belum diisi",IF(AND(F16="Ya",E16="Tidak"),"GUGUR",IF(E16="Ya","Memenuhi","Informasi – perhatikan")))
A17: A4 | B17: Bersedia menandatangani surat pernyataan kerahasiaan dan mematuhi aturan kerahasiaan data klien. | F17: Ya | G17: =IF(E17="","Belum diisi",IF(AND(F17="Ya",E17="Tidak"),"GUGUR",IF(E17="Ya","Memenuhi","Informasi – perhatikan")))
A18: A5 | B18: Tidak memiliki hubungan keluarga, kepemilikan, atau pekerjaan dengan klien KAP (jika ada, sebutkan nama klien di catatan). | F18: Tidak | G18: =IF(E18="","Belum diisi",IF(AND(F18="Ya",E18="Tidak"),"GUGUR",IF(E18="Ya","Memenuhi","Informasi – perhatikan")))
A19: A6 | B19: Memiliki laptop pribadi yang dapat digunakan untuk bekerja. | F19: Tidak | G19: =IF(E19="","Belum diisi",IF(AND(F19="Ya",E19="Tidak"),"GUGUR",IF(E19="Ya","Memenuhi","Informasi – perhatikan")))
A20: A7 | B20: Bersedia dinas luar kota dan menginap bila diperlukan. | F20: Tidak | G20: =IF(E20="","Belum diisi",IF(AND(F20="Ya",E20="Tidak"),"GUGUR",IF(E20="Ya","Memenuhi","Informasi – perhatikan")))
A21: A8 | B21: Surat pengantar/izin magang dari kampus tersedia. | F21: Tidak | G21: =IF(E21="","Belum diisi",IF(AND(F21="Ya",E21="Tidak"),"GUGUR",IF(E21="Ya","Memenuhi","Informasi – perhatikan")))
A22: Status Syarat: | D22: =IF(COUNTBLANK(E14:E21)>0,"BELUM LENGKAP",IF(COUNTIFS(E14:E21,"Tidak",F14:F21,"Ya")>0,"GUGUR","MEMENUHI")) | F22: Kolom 'Bersifat Gugur?' dapat diubah sesuai kebijakan KAP.
A24: BAGIAN B — PENILAIAN KOMPETENSI (skala 1–4; gunakan sheet 'Kunci & Rubrik' sebagai acuan skor)
A25: No. | B25: Kompetensi | C25: Pertanyaan | D25: Ringkasan Jawaban Kandidat | E25: Skor (1–4) | F25: Bobot (%) | G25: Nilai Tertimbang | H25: Catatan / Bukti Interviewer
A26: B1 | B26: Akuntansi | C26: PT ABC membeli persediaan barang dagang secara kredit Rp10.000.000. Dua minggu kemudian PT ABC membayar 60% utangnya. Buatkan jurnal kedua transaksi tersebut dan jelaskan dampaknya terhadap pos neraca. | F26: 7 | G26: =IF(E26="","",(E26-1)/3*F26)
A27: B2 | B27: Akuntansi | C27: Kendaraan operasional dibeli 1 Januari 2025 seharga Rp240.000.000, umur manfaat 4 tahun, tanpa nilai residu, metode garis lurus. Berapa beban penyusutan per tahun dan nilai buku per 31 Desember 2026? Mengapa tanah tidak disusutkan? | F27: 7 | G27: =IF(E27="","",(E27-1)/3*F27)
A28: B3 | B28: Akuntansi | C28: Sebutkan dokumen yang umumnya muncul dalam siklus pembelian, mulai dari permintaan barang sampai pembayaran ke pemasok. | F28: 6 | G28: =IF(E28="","",(E28-1)/3*F28)
A29: B4 | B29: Audit Lapangan | C29: Anda diminta melakukan vouching atas 25 transaksi penambahan aset tetap yang tercatat di buku besar. Apa langkah Anda dan dokumen apa yang Anda periksa? Apa perbedaan vouching dengan tracing? | F29: 9 | G29: =IF(E29="","",(E29-1)/3*F29)
A30: B5 | B30: Audit Lapangan | C30: Saat vouching, nilai di invoice Rp15.500.000, sedangkan di buku besar tercatat Rp15.000.000. Invoice tersebut juga tidak ditandatangani pejabat yang berwenang. Apa yang Anda lakukan? | F30: 7 | G30: =IF(E30="","",(E30-1)/3*F30)
A31: B6 | B31: Audit Lapangan | C31: Anda ikut observasi stock opname di gudang klien. Apa yang harus Anda perhatikan sebelum, saat, dan setelah penghitungan? | F31: 8 | G31: =IF(E31="","",(E31-1)/3*F31)
A32: B7 | B32: Audit Lapangan | C32: Hasil hitung fisik suatu barang 480 unit, sedangkan kartu stok menunjukkan 500 unit. Apa kemungkinan penyebabnya dan apa yang Anda lakukan? | F32: 5 | G32: =IF(E32="","",(E32-1)/3*F32)
A33: B8 | B33: Audit Lapangan | C33: Saat pemeriksaan fisik aset tetap di lokasi klien, apa saja yang Anda cocokkan antara daftar aset tetap dan kondisi di lapangan? | F33: 6 | G33: =IF(E33="","",(E33-1)/3*F33)
A34: B9 | B34: Excel | C34: Tes praktik Excel (file Tes_Praktik_Excel_Kandidat.xlsx, maksimal 15 menit, kandidat menggunakan laptop). | F34: 10 | G34: =IF(E34="","",(E34-1)/3*F34)
A35: B10 | B35: Excel | C35: Bagaimana Anda memastikan angka total di kertas kerja Excel sudah benar dan sesuai dengan sumbernya? | F35: 5 | G35: =IF(E35="","",(E35-1)/3*F35)
A36: B11 | B36: Integritas & Kerahasiaan | C36: Teman kuliah menanyakan nama klien yang Anda kunjungi dan berapa laba perusahaannya, katanya untuk bahan skripsi. Bagaimana respons Anda? | F36: 6 | G36: =IF(E36="","",(E36-1)/3*F36)
A37: B12 | B37: Integritas & Kerahasiaan | C37: Staf klien meminta Anda tidak mencatat selisih stok karena 'nanti akan diperbaiki', lalu menawarkan oleh-oleh. Apa yang Anda lakukan? | F37: 5 | G37: =IF(E37="","",(E37-1)/3*F37)
... A42: B17 | B42: Sikap Kerja | C42: Apa yang Anda ketahui tentang pekerjaan auditor sehari-hari, dan apa yang ingin Anda peroleh dari magang 3 bulan ini? | F42: 4 | G42: =IF(E42="","",(E42-1)/3*F42)
A43: Total | E43: =COUNT(E26:E42)&" / "&COUNTA(C26:C42) | F43: =SUM(F26:F42) | G43: =SUM(G26:G42) | H43: =IF(F43=100,"Bobot total 100% – OK","PERIKSA: bobot total bukan 100%")
A45: RINGKASAN PENILAIAN & REKOMENDASI
B46: Kelompok Kompetensi | D46: Bobot (%) | E46: Indeks (0–100) | F46: Keterangan
B47: Akuntansi | D47: =SUMIF($B$26:$B$42,B47,$F$26:$F$42) | E47: =IF(COUNTIFS($B$26:$B$42,B47,$E$26:$E$42,">=1")<COUNTIF($B$26:$B$42,B47),"",SUMIF($B$26:$B$42,B47,$G$26:$G$42)/D47*100) | F47: Bersama Audit Lapangan membentuk indeks teknis.
B48: Audit Lapangan | D48: =SUMIF($B$26:$B$42,B48,$F$26:$F$42) | E48: =IF(COUNTIFS($B$26:$B$42,B48,$E$26:$E$42,">=1")<COUNTIF($B$26:$B$42,B48),"",SUMIF($B$26:$B$42,B48,$G$26:$G$42)/D48*100) | F48: Bobot terbesar: sesuai tugas utama magang (vouching, stock opname, aset tetap).
...

Sheet Kunci & Rubrik
A1: KUNCI JAWABAN & RUBRIK PENILAIAN
A2: Pegangan interviewer. Jangan diperlihatkan kepada kandidat. Skor diberikan berdasarkan deskriptor, bukan kesan umum.
A4: SKALA UMUM
A5: Skor | B5: Kategori | C5: Deskriptor umum
A6: 4 | B6: Sangat baik | C6: Tepat dan lengkap; mampu menjelaskan alasan; dapat langsung diterapkan tanpa banyak arahan.
A7: 3 | B7: Memadai | C7: Tepat pada poin utama; ada detail yang kurang; cukup dengan arahan singkat.
A8: 2 | B8: Sebagian | C8: Sebagian benar atau ada kekeliruan; memerlukan penjelasan cukup banyak dari auditor.
A9: 1 | B9: Tidak memadai | C9: Salah, tidak dapat menjawab, atau jawaban berisiko (pelanggaran kerahasiaan/integritas).
A11: Tata cara: (1) bacakan pertanyaan apa adanya; (2) gunakan pertanyaan pendalaman bila jawaban masih umum; (3) catat inti jawaban di form; (4) beri skor berdasarkan deskriptor di bawah. Untuk menjaga konsistensi antar-interviewer, 2–3 kandidat pertama sebaiknya diwawancarai berdua dan skornya dibandingkan.
A13: RUBRIK PER PERTANYAAN
A14: No. | B14: Kompetensi | C14: Pertanyaan | D14: Poin Kunci Jawaban | E14: Skor 4 | F14: Skor 3 | G14: Skor 2 | H14: Skor 1 / Red Flag | I14: Pertanyaan Pendalaman
A15: B1 | B15: Akuntansi | C15: PT ABC membeli persediaan barang dagang secara kredit Rp10.000.000. Dua minggu kemudian PT ABC membayar 60% utangnya. Buatkan jurnal kedua transaksi tersebut dan jelaskan dampaknya terhadap pos neraca. | D15: (1) Dr Persediaan 10.000.000 / Cr Utang Usaha 10.000.000. (2) Dr Utang Usaha 6.000.000 / Cr Kas/Bank 6.000.000. Dampak akhir: Persediaan +10 jt, Kas −6 jt, Utang Usaha sisa +4 jt. Belum ada dampak ke laba rugi karena barang belum dijual. Catatan: jurnal metode periodik (Dr Pembelian) dapat diterima jika kandidat menyebut metodenya. | E15: Kedua jurnal benar, dampak neraca benar, dan menjelaskan mengapa belum ada dampak ke laba rugi. | F15: Kedua jurnal benar; penjelasan dampak neraca kurang lengkap. | G15: Hanya satu jurnal benar, atau debit/kredit tertukar lalu dikoreksi setelah diarahkan. | H15: Kedua jurnal salah atau tidak dapat menjawab. | I15: Jika barang tersebut kemudian dijual, akun apa saja yang berubah?
A16: B2 | B16: Akuntansi | C16: Kendaraan operasional dibeli 1 Januari 2025 seharga Rp240.000.000, umur manfaat 4 tahun, tanpa nilai residu, metode garis lurus. Berapa beban penyusutan per tahun dan nilai buku per 31 Desember 2026? Mengapa tanah tidak disusutkan? | D16: Beban penyusutan Rp60 jt/tahun; akumulasi penyusutan s.d. 31-12-2026 Rp120 jt; nilai buku Rp120 jt. Tanah memiliki umur manfaat tidak terbatas sehingga tidak disusutkan (PSAK 216, d/h PSAK 16). | E16: Perhitungan beban, akumulasi, dan nilai buku benar; alasan tanah tidak disusutkan tepat. | F16: Perhitungan benar; alasan tanah kurang tepat atau tidak dijawab. | G16: Hanya beban penyusutan per tahun yang benar. | H16: Perhitungan salah atau tidak dapat menjawab. | I16: Jika kendaraan rusak berat dan tidak lagi digunakan, apa implikasinya terhadap pencatatan?
A17: B3 | B17: Akuntansi | C17: Sebutkan dokumen yang umumnya muncul dalam siklus pembelian, mulai dari permintaan barang sampai pembayaran ke pemasok. | D17: Permintaan pembelian (PR) → Pesanan pembelian (PO) → Surat jalan pemasok & Bukti Penerimaan Barang (BPB) → Faktur/invoice pemasok & faktur pajak → Voucher/bukti pengeluaran kas yang disetujui → Bukti transfer/cek. Jawaban ideal menyebut pencocokan tiga arah (PO – BPB – invoice). | E17: ≥5 dokumen dengan urutan logis dan menyebut pencocokan PO–BPB–invoice. | F17: 4–5 dokumen dengan urutan logis. | G17: 2–3 dokumen atau urutan tidak logis. | H17: ≤1 dokumen atau tidak dapat menjawab. | I17: Mengapa PO, BPB, dan invoice perlu dicocokkan sebelum pembayaran?
A18: B4 | B18: Audit Lapangan | C18: Anda diminta melakukan vouching atas 25 transaksi penambahan aset tetap yang tercatat di buku besar. Apa langkah Anda dan dokumen apa yang Anda periksa? Apa perbedaan vouching dengan tracing? | D18: Arah pengujian: dari catatan (buku besar/daftar aset tetap) ke dokumen sumber. Dokumen: invoice, PO/kontrak, berita acara serah terima/BPB, bukti pembayaran, persetujuan pembelian; kendaraan: BPKB/STNK. Atribut dicocokkan: nama pemasok, tanggal (periode), nilai, deskripsi aset, otorisasi. Beri tickmark dan referensi di kertas kerja. Vouching (catatan → dokumen) menguji keterjadian/keberadaan; tracing (dokumen → catatan) menguji kelengkapan. | E18: Arah vouching benar, menyebut ≥4 dokumen/atribut, dan dapat membedakan vouching–tracing beserta tujuannya. | F18: Arah benar dan dokumen memadai; perbedaan dengan tracing kurang tepat. | G18: Hanya tahu harus 'mencocokkan dokumen', arah dan atribut pengujian tidak jelas. | H18: Tidak memahami vouching. | I18: Apa yang Anda catat di kertas kerja setelah satu sampel selesai diperiksa?
A19: B5 | B19: Audit Lapangan | C19: Saat vouching, nilai di invoice Rp15.500.000, sedangkan di buku besar tercatat Rp15.000.000. Invoice tersebut juga tidak ditandatangani pejabat yang berwenang. Apa yang Anda lakukan? | D19: (a) Mengenali dua isu terpisah: selisih nilai Rp500.000 dan tidak adanya otorisasi (kelemahan pengendalian). (b) Mendokumentasikan di kertas kerja: nomor dokumen, nilai, selisih. (c) Tidak mengoreksi angka sendiri dan tidak menarik kesimpulan. (d) Melapor ke senior/in-charge; permintaan penjelasan ke klien dilakukan atas arahan senior. (e) Menyimpan salinan bukti. | E19: Menyebut kedua isu, mendokumentasikan, dan melapor ke senior. | F19: Mendokumentasikan dan melapor ke senior, tetapi hanya menangkap satu isu. | G19: Langsung menanyakan ke klien tanpa dokumentasi dan tanpa melapor ke senior. | H19: RED FLAG: mengabaikan karena nilainya kecil, atau mengubah angka sendiri. | I19: Menurut Anda, mana yang lebih serius: selisih nilai atau tidak adanya tanda tangan? Mengapa?
A20: B6 | B20: Audit Lapangan | C20: Anda ikut observasi stock opname di gudang klien. Apa yang harus Anda perhatikan sebelum, saat, dan setelah penghitungan? | D20: Sebelum: memahami instruksi opname klien; mencatat dokumen terakhir (surat jalan/BPB) untuk cut-off; memastikan tidak ada mutasi barang selama hitung. Saat: test count dua arah (fisik → daftar dan daftar → fisik); tag/kartu hitung bernomor urut; mencatat barang rusak/usang/kedaluwarsa; barang milik pihak lain (konsinyasi/titipan) dipisahkan. Setelah: salinan hasil hitung/berita acara yang ditandatangani; kontrol nomor tag terpakai dan tidak terpakai. | E20: Poin tepat pada ketiga tahap, termasuk cut-off dan test count. | F20: Poin pada tahap 'saat' lengkap; tahap sebelum/sesudah hanya sebagian. | G20: Hanya 'ikut menghitung barang' tanpa prosedur pengendalian. | H20: Tidak memahami tujuan observasi stock opname. | I20: Ada barang titipan pelanggan di gudang yang sama. Bagaimana perlakuannya?
A21: B7 | B21: Audit Lapangan | C21: Hasil hitung fisik suatu barang 480 unit, sedangkan kartu stok menunjukkan 500 unit. Apa kemungkinan penyebabnya dan apa yang Anda lakukan? | D21: Penyebab: cut-off (barang sudah dikirim tetapi belum dicatat, atau sebaliknya); salah hitung; perbedaan satuan (dus vs pcs); barang di lokasi lain/dipinjam/di bagian produksi; salah catat kartu stok; kehilangan. Tindakan: hitung ulang bersama petugas klien; periksa dokumen mutasi terakhir; catat di kertas kerja; lapor ke senior; tidak mengubah angka. | E21: ≥4 kemungkinan penyebab dan tindakan tepat. | F21: 2–3 kemungkinan penyebab dan tindakan tepat. | G21: Hanya menyebut 'barang hilang', atau tindakan kurang tepat. | H21: RED FLAG: menyesuaikan angka sendiri; atau tidak dapat menjawab. | I21: Bagaimana Anda tahu bahwa selisih ini disebabkan masalah cut-off?
A22: B8 | B22: Audit Lapangan | C22: Saat pemeriksaan fisik aset tetap di lokasi klien, apa saja yang Anda cocokkan antara daftar aset tetap dan kondisi di lapangan? | D22: Dua arah: aset di daftar ada fisiknya (keberadaan) dan aset fisik tercatat di daftar (kelengkapan). Kode/tag aset; merek, tipe, nomor seri; kendaraan: nomor polisi/rangka dan BPKB/STNK atas nama perusahaan; lokasi; kondisi (rusak/tidak dipakai → indikasi penurunan nilai atau penghapusan); dokumentasi foto dengan izin dan berita acara. | E22: ≥5 poin, termasuk pemeriksaan dua arah dan kondisi aset. | F22: 3–4 poin. | G22: Hanya 'mengecek aset ada atau tidak'. | H22: Tidak dapat menjawab. | I22: Jika ada mesin yang ditemukan tidak terpakai dan berkarat, apa yang Anda lakukan?
A23: B9 | B23: Excel | C23: Tes praktik Excel (file Tes_Praktik_Excel_Kandidat.xlsx, maksimal 15 menit, kandidat menggunakan laptop). | D23: Lihat sheet 'Kunci Tes Excel' (6 tugas). Interviewer memeriksa hasil dan apakah kandidat memakai rumus, bukan mengetik angka manual. | E23: 6 tugas benar dengan rumus, selesai ≤15 menit. | F23: 4–5 tugas benar dengan rumus. | G23: 2–3 tugas benar, atau hasil benar tetapi angka diketik manual. | H23: ≤1 tugas benar. | I23: Minta kandidat menjelaskan satu rumus yang dipakainya.
A24: B10 | B24: Excel | C24: Bagaimana Anda memastikan angka total di kertas kerja Excel sudah benar dan sesuai dengan sumbernya? | D24: Footing dan cross-footing (total baris = total kolom); cocokkan ke sumber (buku besar/neraca saldo); periksa range rumus mencakup semua baris; periksa tidak ada angka yang diketik menimpa rumus; periksa referensi absolut/relatif; beri tickmark dan referensi. | E24: ≥4 poin, termasuk mencocokkan ke sumber. | F24: 2–3 poin. | G24: Hanya 'dicek ulang' tanpa metode yang jelas. | H24: Tidak dapat menjawab. | I24: Pernahkah Anda menemukan kesalahan rumus di pekerjaan Anda sendiri? Bagaimana menemukannya?
A25: B11 | B25: Integritas & Kerahasiaan | C25: Teman kuliah menanyakan nama klien yang Anda kunjungi dan berapa laba perusahaannya, katanya untuk bahan skripsi. Bagaimana respons Anda? | D25: Menolak memberi informasi apa pun, termasuk nama klien. Alasan: kewajiban kerahasiaan profesi dan perjanjian kerahasiaan dengan KAP. Tidak memotret/mengunggah dokumen atau lokasi klien ke media sosial. Kebutuhan data skripsi diarahkan ke data publik atau prosedur resmi KAP. | E25: Menolak sepenuhnya, menjelaskan alasan, dan menyebut larangan mengunggah foto/dokumen. | F25: Menolak sepenuhnya; alasan kurang lengkap. | G25: Menolak memberi angka, tetapi bersedia menyebut nama klien. | H25: RED FLAG: bersedia memberikan data klien. | I25: Bolehkah Anda memotret dokumen klien dengan HP pribadi agar pekerjaan lebih cepat?
... A31: B17 | B31: Sikap Kerja | C31: Apa yang Anda ketahui tentang pekerjaan auditor sehari-hari, dan apa yang ingin Anda peroleh dari magang 3 bulan ini? | D31: Pemahaman realistis: banyak memeriksa dokumen, kunjungan ke klien, tenggat ketat, lembur pada musim sibuk. Tujuan belajar spesifik. | E31: Gambaran pekerjaan realistis dan tujuan belajar spesifik. | F31: Salah satunya saja. | G31: Jawaban umum ('menambah pengalaman'). | H31: Ekspektasi tidak realistis, atau magang semata untuk memenuhi SKS. | I31: —

Sheet Kunci Tes Excel
A1: KUNCI TES PRAKTIK EXCEL
A2: Jawaban dihitung otomatis dengan rumus. Bandingkan hasil kandidat dengan angka di sini.
A4: Klien (fiktif): PT ABC — Stock opname 31 Desember
A6: TUGAS
A7: 1 | B7: Kolom F: hitung Selisih Qty = Qty Hitung Fisik − Qty Kartu Stok.
A8: 2 | B8: Kolom G: ambil Harga Satuan dari tabel Master Harga (kolom K–L) menggunakan rumus pencarian (VLOOKUP/INDEX-MATCH/XLOOKUP).
A9: 3 | B9: Kolom H: hitung Nilai Selisih = Selisih Qty × Harga Satuan.
A10: 4 | B10: Kolom I: isi keterangan "Selisih" jika Selisih Qty tidak sama dengan nol, dan "Sesuai" jika nol (gunakan rumus IF).
A11: 5 | B11: Tabel Ringkasan: hitung jumlah item yang selisih (COUNTIF) dan total Nilai Selisih per kategori (SUMIF).
A12: 6 | B12: Buat cek: total Nilai Selisih per kategori harus sama dengan total kolom H. Tampilkan "OK" jika sama.
K13: MASTER HARGA
A14: Kode | B14: Nama Barang | C14: Kategori | D14: Qty Kartu Stok | E14: Qty Hitung Fisik | F14: Selisih Qty | G14: Harga Satuan (Rp) | H14: Nilai Selisih (Rp) | I14: Keterangan | K14: Kode | L14: Harga Satuan (Rp)
A15: BB-001 | B15: Biji Plastik PP (kg) | C15: Bahan Baku | D15: 1250 | E15: 1250 | F15: =E15-D15 | G15: =VLOOKUP(A15,$K$15:$L$26,2,FALSE) | H15: =F15*G15 | I15: =IF(F15<>0,"Selisih","Sesuai") | K15: SC-203 | L15: 72000
A16: BB-002 | B16: Pigmen Warna Merah (kg) | C16: Bahan Baku | D16: 85 | E16: 80 | F16: =E16-D16 | G16: =VLOOKUP(A16,$K$15:$L$26,2,FALSE) | H16: =F16*G16 | I16: =IF(F16<>0,"Selisih","Sesuai") | K16: BJ-104 | L16: 6200
A17: BB-003 | B17: Karton Box Ukuran A (pcs) | C17: Bahan Baku | D17: 3400 | E17: 3400 | F17: =E17-D17 | G17: =VLOOKUP(A17,$K$15:$L$26,2,FALSE) | H17: =F17*G17 | I17: =IF(F17<>0,"Selisih","Sesuai") | K17: BB-003 | L17: 4250
A18: BB-004 | B18: Lakban Bening (roll) | C18: Bahan Baku | D18: 240 | E18: 236 | F18: =E18-D18 | G18: =VLOOKUP(A18,$K$15:$L$26,2,FALSE) | H18: =F18*G18 | I18: =IF(F18<>0,"Selisih","Sesuai") | K18: SC-201 | L18: 1350000
A19: BJ-101 | B19: Ember 20 Liter (pcs) | C19: Barang Jadi | D19: 620 | E19: 620 | F19: =E19-D19 | G19: =VLOOKUP(A19,$K$15:$L$26,2,FALSE) | H19: =F19*G19 | I19: =IF(F19<>0,"Selisih","Sesuai") | K19: BJ-102 | L19: 45000
A20: BJ-102 | B20: Kursi Plastik (pcs) | C20: Barang Jadi | D20: 410 | E20: 398 | F20: =E20-D20 | G20: =VLOOKUP(A20,$K$15:$L$26,2,FALSE) | H20: =F20*G20 | I20: =IF(F20<>0,"Selisih","Sesuai") | K20: BB-001 | L20: 18500
A21: BJ-103 | B21: Keranjang Serbaguna (pcs) | C21: Barang Jadi | D21: 950 | E21: 955 | F21: =E21-D21 | G21: =VLOOKUP(A21,$K$15:$L$26,2,FALSE) | H21: =F21*G21 | I21: =IF(F21<>0,"Selisih","Sesuai") | K21: SC-204 | L21: 1120000
A22: BJ-104 | B22: Gayung (pcs) | C22: Barang Jadi | D22: 1800 | E22: 1800 | F22: =E22-D22 | G22: =VLOOKUP(A22,$K$15:$L$26,2,FALSE) | H22: =F22*G22 | I22: =IF(F22<>0,"Selisih","Sesuai") | K22: BJ-101 | L22: 27500
A23: SC-201 | B23: Mata Pisau Mesin Cetak (pcs) | C23: Suku Cadang | D23: 24 | E23: 24 | F23: =E23-D23 | G23: =VLOOKUP(A23,$K$15:$L$26,2,FALSE) | H23: =F23*G23 | I23: =IF(F23<>0,"Selisih","Sesuai") | K23: BB-004 | L23: 9800
A24: SC-202 | B24: V-Belt Tipe B (pcs) | C24: Suku Cadang | D24: 36 | E24: 33 | F24: =E24-D24 | G24: =VLOOKUP(A24,$K$15:$L$26,2,FALSE) | H24: =F24*G24 | I24: =IF(F24<>0,"Selisih","Sesuai") | K24: SC-202 | L24: 185000
A25: SC-203 | B25: Bearing 6205 (pcs) | C25: Suku Cadang | D25: 60 | E25: 60 | F25: =E25-D25 | G25: =VLOOKUP(A25,$K$15:$L$26,2,FALSE) | H25: =F25*G25 | I25: =IF(F25<>0,"Selisih","Sesuai") | K25: BJ-103 | L25: 15750
A26: SC-204 | B26: Oli Hidrolik 20 L (pail) | C26: Suku Cadang | D26: 15 | E26: 14 | F26: =E26-D26 | G26: =VLOOKUP(A26,$K$15:$L$26,2,FALSE) | H26: =F26*G26 | I26: =IF(F26<>0,"Selisih","Sesuai") | K26: BB-002 | L26: 62000
A27: Total | H27: =SUM(H15:H26)
A29: RINGKASAN
A30: Jumlah item selisih | D30: =COUNTIF(I15:I26,"Selisih")
A31: Kategori | D31: Total Nilai Selisih (Rp)
A32: Bahan Baku | D32: =SUMIF($C$15:$C$26,A32,$H$15:$H$26)
A33: Barang Jadi | D33: =SUMIF($C$15:$C$26,A33,$H$15:$H$26)
A34: Suku Cadang | D34: =SUMIF($C$15:$C$26,A34,$H$15:$H$26)
A35: Total per kategori | D35: =SUM(D32:D34)
A36: Cek (Total per kategori = Total kolom H) | D36: =IF(ROUND(D35-H27,0)=0,"OK","TIDAK SAMA")
A38: Panduan skor (pertanyaan B9): hitung tugas yang benar DAN dikerjakan dengan rumus.
A39: Tugas 2: VLOOKUP, INDEX-MATCH, atau XLOOKUP sama-sama diterima; pastikan kandidat memakai pencocokan persis (FALSE/0).
A40: Kesalahan umum: VLOOKUP tanpa FALSE (hasil salah karena Master Harga tidak urut), range tidak dikunci ($), selisih dihitung terbalik (Kartu − Fisik).
A41: Nilai bertanda negatif berarti fisik lebih sedikit dari catatan (potensi kehilangan/cut-off). Kandidat yang menyadari hal ini menunjukkan pemahaman, bukan sekadar teknik.

Sheet Rekap Kandidat
A1: REKAP & PERINGKAT KANDIDAT
A2: Tempel (Paste Values) baris 'Data untuk Rekap' dari setiap form ke kolom B–P. Kolom Q–T terhitung otomatis.
A4: No. | B4: Nama Mahasiswa | C4: Universitas | D4: Interviewer | E4: Tgl Wawancara | F4: Status Syarat | G4: Akuntansi | H4: Audit Lapangan | I4: Excel | J4: Integritas | K4: Sikap Kerja | L4: Indeks Teknis | M4: Nilai Akhir | N4: Rekomendasi Sistem | O4: Bersedia Luar Kota | P4: Keputusan Akhir | Q4: Layak Diperingkat | R4: Nilai Peringkat | S4: Peringkat | T4: Usulan
A5: 1 | Q5: =IF(B5="","",IF(AND(F5="MEMENUHI",OR(N5="SANGAT DIREKOMENDASIKAN",N5="DIREKOMENDASIKAN",N5="DIPERTIMBANGKAN")),"Ya","Tidak")) | R5: =IF(Q5<>"Ya","",M5+IF(O5="Ya",0.01,0)+L5/10000) | S5: =IF(R5="","",COUNTIF($R$5:$R$64,">"&R5)+1) | T5: =IF(B5="","",IF(Q5<>"Ya","Tidak Lolos",IF(S5<=Parameter!$C$9,"Masuk Kuota","Cadangan")))
A6: 2 | Q6: =IF(B6="","",IF(AND(F6="MEMENUHI",OR(N6="SANGAT DIREKOMENDASIKAN",N6="DIREKOMENDASIKAN",N6="DIPERTIMBANGKAN")),"Ya","Tidak")) | R6: =IF(Q6<>"Ya","",M6+IF(O6="Ya",0.01,0)+L6/10000) | S6: =IF(R6="","",COUNTIF($R$5:$R$64,">"&R6)+1) | T6: =IF(B6="","",IF(Q6<>"Ya","Tidak Lolos",IF(S6<=Parameter!$C$9,"Masuk Kuota","Cadangan")))
A7: 3 | Q7: =IF(B7="","",IF(AND(F7="MEMENUHI",OR(N7="SANGAT DIREKOMENDASIKAN",N7="DIREKOMENDASIKAN",N7="DIPERTIMBANGKAN")),"Ya","Tidak")) | R7: =IF(Q7<>"Ya","",M7+IF(O7="Ya",0.01,0)+L7/10000) | S7: =IF(R7="","",COUNTIF($R$5:$R$64,">"&R7)+1) | T7: =IF(B7="","",IF(Q7<>"Ya","Tidak Lolos",IF(S7<=Parameter!$C$9,"Masuk Kuota","Cadangan")))
A8: 4 | Q8: =IF(B8="","",IF(AND(F8="MEMENUHI",OR(N8="SANGAT DIREKOMENDASIKAN",N8="DIREKOMENDASIKAN",N8="DIPERTIMBANGKAN")),"Ya","Tidak")) | R8: =IF(Q8<>"Ya","",M8+IF(O8="Ya",0.01,0)+L8/10000) | S8: =IF(R8="","",COUNTIF($R$5:$R$64,">"&R8)+1) | T8: =IF(B8="","",IF(Q8<>"Ya","Tidak Lolos",IF(S8<=Parameter!$C$9,"Masuk Kuota","Cadangan")))
A9: 5 | Q9: =IF(B9="","",IF(AND(F9="MEMENUHI",OR(N9="SANGAT DIREKOMENDASIKAN",N9="DIREKOMENDASIKAN",N9="DIPERTIMBANGKAN")),"Ya","Tidak")) | R9: =IF(Q9<>"Ya","",M9+IF(O9="Ya",0.01,0)+L9/10000) | S9: =IF(R9="","",COUNTIF($R$5:$R$64,">"&R9)+1) | T9: =IF(B9="","",IF(Q9<>"Ya","Tidak Lolos",IF(S9<=Parameter!$C$9,"Masuk Kuota","Cadangan")))
A10: 6 | Q10: =IF(B10="","",IF(AND(F10="MEMENUHI",OR(N10="SANGAT DIREKOMENDASIKAN",N10="DIREKOMENDASIKAN",N10="DIPERTIMBANGKAN")),"Ya","Tidak")) | R10: =IF(Q10<>"Ya","",M10+IF(O10="Ya",0.01,0)+L10/10000) | S10: =IF(R10="","",COUNTIF($R$5:$R$64,">"&R10)+1) | T10: =IF(B10="","",IF(Q10<>"Ya","Tidak Lolos",IF(S10<=Parameter!$C$9,"Masuk Kuota","Cadangan")))
A11: 7 | Q11: =IF(B11="","",IF(AND(F11="MEMENUHI",OR(N11="SANGAT DIREKOMENDASIKAN",N11="DIREKOMENDASIKAN",N11="DIPERTIMBANGKAN")),"Ya","Tidak")) | R11: =IF(Q11<>"Ya","",M11+IF(O11="Ya",0.01,0)+L11/10000) | S11: =IF(R11="","",COUNTIF($R$5:$R$64,">"&R11)+1) | T11: =IF(B11="","",IF(Q11<>"Ya","Tidak Lolos",IF(S11<=Parameter!$C$9,"Masuk Kuota","Cadangan")))
A12: 8 | Q12: =IF(B12="","",IF(AND(F12="MEMENUHI",OR(N12="SANGAT DIREKOMENDASIKAN",N12="DIREKOMENDASIKAN",N12="DIPERTIMBANGKAN")),"Ya","Tidak")) | R12: =IF(Q12<>"Ya","",M12+IF(O12="Ya",0.01,0)+L12/10000) | S12: =IF(R12="","",COUNTIF($R$5:$R$64,">"&R12)+1) | T12: =IF(B12="","",IF(Q12<>"Ya","Tidak Lolos",IF(S12<=Parameter!$C$9,"Masuk Kuota","Cadangan")))
A13: 9 | Q13: =IF(B13="","",IF(AND(F13="MEMENUHI",OR(N13="SANGAT DIREKOMENDASIKAN",N13="DIREKOMENDASIKAN",N13="DIPERTIMBANGKAN")),"Ya","Tidak")) | R13: =IF(Q13<>"Ya","",M13+IF(O13="Ya",0.01,0)+L13/10000) | S13: =IF(R13="","",COUNTIF($R$5:$R$64,">"&R13)+1) | T13: =IF(B13="","",IF(Q13<>"Ya","Tidak Lolos",IF(S13<=Parameter!$C$9,"Masuk Kuota","Cadangan")))
A14: 10 | Q14: =IF(B14="","",IF(AND(F14="MEMENUHI",OR(N14="SANGAT DIREKOMENDASIKAN",N14="DIREKOMENDASIKAN",N14="DIPERTIMBANGKAN")),"Ya","Tidak")) | R14: =IF(Q14<>"Ya","",M14+IF(O14="Ya",0.01,0)+L14/10000) | S14: =IF(R14="","",COUNTIF($R$5:$R$64,">"&R14)+1) | T14: =IF(B14="","",IF(Q14<>"Ya","Tidak Lolos",IF(S14<=Parameter!$C$9,"Masuk Kuota","Cadangan")))
A15: 11 | Q15: =IF(B15="","",IF(AND(F15="MEMENUHI",OR(N15="SANGAT DIREKOMENDASIKAN",N15="DIREKOMENDASIKAN",N15="DIPERTIMBANGKAN")),"Ya","Tidak")) | R15: =IF(Q15<>"Ya","",M15+IF(O15="Ya",0.01,0)+L15/10000) | S15: =IF(R15="","",COUNTIF($R$5:$R$64,">"&R15)+1) | T15: =IF(B15="","",IF(Q15<>"Ya","Tidak Lolos",IF(S15<=Parameter!$C$9,"Masuk Kuota","Cadangan")))
A16: 12 | Q16: =IF(B16="","",IF(AND(F16="MEMENUHI",OR(N16="SANGAT DIREKOMENDASIKAN",N16="DIREKOMENDASIKAN",N16="DIPERTIMBANGKAN")),"Ya","Tidak")) | R16: =IF(Q16<>"Ya","",M16+IF(O16="Ya",0.01,0)+L16/10000) | S16: =IF(R16="","",COUNTIF($R$5:$R$64,">"&R16)+1) | T16: =IF(B16="","",IF(Q16<>"Ya","Tidak Lolos",IF(S16<=Parameter!$C$9,"Masuk Kuota","Cadangan")))
... A64: 60 | Q64: =IF(B64="","",IF(AND(F64="MEMENUHI",OR(N64="SANGAT DIREKOMENDASIKAN",N64="DIREKOMENDASIKAN",N64="DIPERTIMBANGKAN")),"Ya","Tidak")) | R64: =IF(Q64<>"Ya","",M64+IF(O64="Ya",0.01,0)+L64/10000) | S64: =IF(R64="","",COUNTIF($R$5:$R$64,">"&R64)+1) | T64: =IF(B64="","",IF(Q64<>"Ya","Tidak Lolos",IF(S64<=Parameter!$C$9,"Masuk Kuota","Cadangan")))
A65: Nilai Peringkat = Nilai Akhir + 0,01 bila bersedia dinas luar kota + Indeks Teknis/10.000 (pemecah nilai seri; dinas luar kota hanya penentu bila nilai sama, bukan syarat). Kandidat 'Tidak Lolos' tidak diberi peringkat.
A67: RINGKASAN | G67: KALIBRASI ANTAR-INTERVIEWER
A68: Jumlah kandidat diwawancarai | E68: =COUNTA(B5:B64) | G68: Nama Interviewer | I68: Jumlah Kandidat | J68: Rata-rata Nilai | K68: Selisih dari Rata-rata | L68: Status
A69: Layak diperingkat | E69: =COUNTIF(Q5:Q64,"Ya") | I69: =IF(G69="","",COUNTIF($D$5:$D$64,G69)) | J69: =IF(OR(G69="",I69=0),"",AVERAGEIF($D$5:$D$64,G69,$M$5:$M$64)) | K69: =IF(J69="","",J69-$E$73) | L69: =IF(K69="","",IF(ABS(K69)>Parameter!$C$10,"Perlu kalibrasi","Wajar"))
A70: Masuk kuota | E70: =COUNTIF(T5:T64,"Masuk Kuota") | I70: =IF(G70="","",COUNTIF($D$5:$D$64,G70)) | J70: =IF(OR(G70="",I70=0),"",AVERAGEIF($D$5:$D$64,G70,$M$5:$M$64)) | K70: =IF(J70="","",J70-$E$73) | L70: =IF(K70="","",IF(ABS(K70)>Parameter!$C$10,"Perlu kalibrasi","Wajar"))
A71: Cadangan | E71: =COUNTIF(T5:T64,"Cadangan") | I71: =IF(G71="","",COUNTIF($D$5:$D$64,G71)) | J71: =IF(OR(G71="",I71=0),"",AVERAGEIF($D$5:$D$64,G71,$M$5:$M$64)) | K71: =IF(J71="","",J71-$E$73) | L71: =IF(K71="","",IF(ABS(K71)>Parameter!$C$10,"Perlu kalibrasi","Wajar"))
A72: Kuota | E72: =Parameter!$C$9 | I72: =IF(G72="","",COUNTIF($D$5:$D$64,G72)) | J72: =IF(OR(G72="",I72=0),"",AVERAGEIF($D$5:$D$64,G72,$M$5:$M$64)) | K72: =IF(J72="","",J72-$E$73) | L72: =IF(K72="","",IF(ABS(K72)>Parameter!$C$10,"Perlu kalibrasi","Wajar"))
A73: Rata-rata nilai akhir seluruh kandidat | E73: =IFERROR(AVERAGE(M5:M64),"") | I73: =IF(G73="","",COUNTIF($D$5:$D$64,G73)) | J73: =IF(OR(G73="",I73=0),"",AVERAGEIF($D$5:$D$64,G73,$M$5:$M$64)) | K73: =IF(J73="","",J73-$E$73) | L73: =IF(K73="","",IF(ABS(K73)>Parameter!$C$10,"Perlu kalibrasi","Wajar"))
I74: =IF(G74="","",COUNTIF($D$5:$D$64,G74)) | J74: =IF(OR(G74="",I74=0),"",AVERAGEIF($D$5:$D$64,G74,$M$5:$M$64)) | K74: =IF(J74="","",J74-$E$73) | L74: =IF(K74="","",IF(ABS(K74)>Parameter!$C$10,"Perlu kalibrasi","Wajar"))

Sheet Parameter
A1: PARAMETER PENILAIAN
A2: Ubah nilai di kolom C (sel berwarna blush) bila kebijakan KAP berbeda. Semua sheet mengacu ke sini.
A3: No. | B3: Parameter | C3: Nilai | D3: Keterangan
A4: 1 | B4: Batas SANGAT DIREKOMENDASIKAN (nilai akhir ≥) | C4: 75 | D4: Setara rata-rata skor ±3,25 dari skala 1–4.
A5: 2 | B5: Batas DIREKOMENDASIKAN (nilai akhir ≥) | C5: 60 | D5: Setara rata-rata skor ±2,8.
A6: 3 | B6: Batas DIPERTIMBANGKAN (nilai akhir ≥) | C6: 45 | D6: Di bawah batas ini: TIDAK DIREKOMENDASIKAN.
A7: 4 | B7: Indeks teknis minimum (Akuntansi + Audit Lapangan) | C7: 50 | D7: Di bawah nilai ini kandidat tidak direkomendasikan, berapa pun nilai akhirnya.
A8: 5 | B8: Skor minimum per pertanyaan Integritas & Kerahasiaan | C8: 2 | D8: Skor 1 pada salah satu pertanyaan integritas = red flag.
A9: 6 | B9: Kuota mahasiswa magang | C9: 15 | D9: Dipakai di sheet Rekap Kandidat untuk menentukan 'Masuk Kuota' vs 'Cadangan'.
A10: 7 | B10: Toleransi selisih rata-rata nilai antar-interviewer (poin) | C10: 10 | D10: Selisih di atas ini menandakan interviewer terlalu longgar/ketat; perlu kalibrasi.
A12: Rumus nilai: setiap pertanyaan dinilai 1–4, dikonversi ke 0–100 dengan (skor − 1) ÷ 3 × 100, lalu dibobot. Skor 1 = 0 poin, skor 2 = 33, skor 3 = 67, skor 4 = 100. Tidak ada nilai dasar untuk jawaban yang tidak memadai.
